Workbook

Sheet Смета
B1: Смета потенциального объекта
B2: Синие значения — вводные, их можно менять. Чёрные — формулы.
B4: Организация (наша) | C4: ТОО «IC Line»
B5: Наименование объекта (клиент) | C5: ТОО «Орда Трейдинг»
B6: Адрес объекта | C6: г. Алматы, ул. Кабанбай батыра, д. 147
B7: Деятельность клиента | C7: торговая компания
B8: Тип проекта | C8: отдельно стоящее здание
B9: Кол-во объектов | C9: 1
B10: Количество этажей | C10: 5
B11: Количество входных групп | C11: 1
B12: График работы объекта | C12: 5/2 09:00–18:00
B13: Тип уборки | C13: базовая + поддерживающая
B14: Площадь внутренних помещений, м² | C14: 1150
B15: Площадь прилегающей территории, м² | C15: нет
B16: Паркинг | C16: нет
B17: Количество санузлов | C17: 4
B18: Действующая клининговая компания | C18: ТОО «Блеск Сервис»
B19: Действующая расстановка ОПУ | C19: база 6 чел., поддержка 2 чел.
B20: Вид закупки | C20: тендер
B21: Бюджет клиента в год, тг с НДС | C21: 37200000
B22: Бюджет клиента в месяц, тг с НДС | C22: =C21/12
B23: Смету составил | C23: Менеджер по продажам Сериков Д.
B24: Дата | C24: 05.10.2026
A26: ФОТ операторов (самозанятые)
A27: № | B27: Должность | C27: Кол-во, чел. | D27: Ставка в месяц, тг | E27: Сумма в месяц, тг | F27: График работы | I27: Примечание
A28: 1 | B28: ОПУ дневная базовая уборка | C28: 6 | D28: 118000 | E28: =C28*D28 | F28: 5/2 07:00–11:00
A29: 2 | B29: ОПУ поддержка (санузлы, холл, кухни) | C29: 1 | D29: 192000 | E29: =C29*D29 | F29: 5/2 09:00–18:00
A30: 3 | B30: ОПУ поддержка вечер | C30: 1 | D30: 98000 | E30: =C30*D30 | F30: 5/2 14:00–18:00
A31: 4 | B31: Генеральная уборка (6 ОПУ × 16 000 тг, раз в квартал → в месяц) | C31: 6 | D31: =16000*4/12 | E31: =C31*D31 | F31: 1 раз в квартал, суббота
A32: 5 | B32: Расходы Платформы Занятости (6% сверху, gross-up) | E32: =SUM(E28:E31)*6%/(1-6%)
A33: ИТОГО | E33: =SUM(E28:E32)
A35: Моющие средства и расходные материалы для уборки
A36: № | B36: Наименование | C36: Ед. изм. | D36: Кол-во за период | E36: Цена без НДС, тг | F36: Цена с НДС, тг | G36: Период, мес. | H36: В месяц без НДС, тг | I36: Примечание
A37: 1 | B37: Средство для стёкол и зеркал | C37: л | D37: 6 | E37: =F37/1.16 | F37: 690 | G37: 1 | H37: =D37*E37/G37
A38: 2 | B38: Универсальное средство для пола | C38: л | D38: 14 | E38: =F38/1.16 | F38: 870 | G38: 1 | H38: =D38*E38/G38
A39: 3 | B39: Средство для сантехники, гель | C39: шт | D39: 10 | E39: =F39/1.16 | F39: 1250 | G39: 1 | H39: =D39*E39/G39
A40: 4 | B40: Дезинфицирующие таблетки (300 шт.) | C40: банка | D40: 1 | E40: =F40/1.16 | F40: 2950 | G40: 1 | H40: =D40*E40/G40
A41: 5 | B41: Полироль для мебели, аэрозоль | C41: шт | D41: 4 | E41: =F41/1.16 | F41: 2250 | G41: 1 | H41: =D41*E41/G41
A42: 6 | B42: Чистящий крем | C42: шт | D42: 6 | E42: =F42/1.16 | F42: 720 | G42: 1 | H42: =D42*E42/G42
A43: 7 | B43: Пакеты для мусора 120 л | C43: шт | D43: 220 | E43: =F43/1.16 | F43: 42 | G43: 1 | H43: =D43*E43/G43
...

Sheet Свод по смете
A1: СВОД ПО СМЕТЕ
A3: Статья | B3: В месяц без НДС, тг | C3: В год без НДС, тг | D3: Доля в цене | E3: Как считается
A4: ФОТ операторов с расходами платформы | B4: =Смета!E33 | C4: =B4*12 | D4: =B4/$B$15 | E4: Смета, блок ФОТ
A5: Моющие средства и расходные материалы | B5: =Смета!H48 | C5: =B5*12 | D5: =B5/$B$15 | E5: Смета
A6: Расходные материалы гигиены | B6: =Смета!H55 | C6: =B6*12 | D6: =B6/$B$15 | E6: Смета
A7: Инвентарь | B7: =Смета!H64 | C7: =B7*12 | D7: =B7/$B$15 | E7: Смета, на срок службы
A8: Оборудование | B8: =Смета!H70 | C8: =B8*12 | D8: =B8/$B$15 | E8: Смета, амортизация
A9: Спецодежда | B9: =Смета!H76 | C9: =B9*12 | D9: =B9/$B$15 | E9: Смета
A10: СЕБЕСТОИМОСТЬ | B10: =SUM(B4:B9) | C10: =B10*12 | D10: =B10/$B$15 | E10: Сумма статей
A11: Вознаграждение субподрядчика | B11: =B10*0.101/0.9 | C11: =B11*12 | D11: =B11/$B$15 | E11: Себестоимость × 0,101 / 0,9 (≈10% бюджета субподрядчика)
A12: Административные расходы субподрядчика | B12: =(B10+B11)*0.01/0.99 | C12: =B12*12 | D12: =B12/$B$15 | E12: (Себестоимость + вознаграждение) × 0,01 / 0,99
A13: БЮДЖЕТ СУБПОДРЯДЧИКА | B13: =B10+B11+B12 | C13: =B13*12 | D13: =B13/$B$15 | E13: Столько IC Line платит субподрядчику в месяц
A14: Маржа IC Line | B14: =B13*15/85 | C14: =B14*12 | D14: =B14/$B$15 | E14: Бюджет субподрядчика × 15/85 (= 15% цены без НДС)
A15: ЦЕНА КЛИЕНТУ БЕЗ НДС | B15: =B13+B14 | C15: =B15*12 | D15: =B15/$B$15
A16: НДС 16% | B16: =B15*0.16 | C16: =B16*12
A17: ЦЕНА КЛИЕНТУ С НДС | B17: =B15+B16 | C17: =B17*12
A19: Бюджет клиента в месяц с НДС | B19: =Смета!C22
A20: Запас (+) / превышение (−) бюджета | B20: =B19-B17

Sheet БДР
A1: БЮДЖЕТ ДОХОДОВ И РАСХОДОВ ПО ОБЪЕКТУ (12 месяцев)
A2: Клиент: ТОО «Орда Трейдинг». Все суммы — тенге без НДС, кроме строки поступлений.
A4: Статья | B4: окт.26 | C4: ноя.26 | D4: дек.26 | E4: янв.27 | F4: фев.27 | G4: мар.27 | H4: апр.27 | I4: май.27 | J4: июн.27 | K4: июл.27 | L4: авг.27 | M4: сен.27 | N4: Итого за год
A5: Поступления от клиента (с НДС) | B5: ='Свод по смете'!$B$17 | C5: ='Свод по смете'!$B$17 | D5: ='Свод по смете'!$B$17 | E5: ='Свод по смете'!$B$17 | F5: ='Свод по смете'!$B$17 | G5: ='Свод по смете'!$B$17 | H5: ='Свод по смете'!$B$17 | I5: ='Свод по смете'!$B$17 | ... M5: ='Свод по смете'!$B$17 | N5: =SUM(B5:M5)
A6: Выручка без НДС | B6: ='Свод по смете'!$B$15 | C6: ='Свод по смете'!$B$15 | D6: ='Свод по смете'!$B$15 | E6: ='Свод по смете'!$B$15 | F6: ='Свод по смете'!$B$15 | G6: ='Свод по смете'!$B$15 | H6: ='Свод по смете'!$B$15 | I6: ='Свод по смете'!$B$15 | ... M6: ='Свод по смете'!$B$15 | N6: =SUM(B6:M6)
A7: ФОТ операторов с расходами платформы | B7: =-'Свод по смете'!$B$4 | C7: =-'Свод по смете'!$B$4 | D7: =-'Свод по смете'!$B$4 | E7: =-'Свод по смете'!$B$4 | F7: =-'Свод по смете'!$B$4 | G7: =-'Свод по смете'!$B$4 | H7: =-'Свод по смете'!$B$4 | I7: =-'Свод по смете'!$B$4 | ... M7: =-'Свод по смете'!$B$4 | N7: =SUM(B7:M7)
A8: Материалы, гигиена, инвентарь, спецодежда | B8: =-('Свод по смете'!$B$5+'Свод по смете'!$B$6+'Свод по смете'!$B$7+'Свод по смете'!$B$9) | C8: =-('Свод по смете'!$B$5+'Свод по смете'!$B$6+'Свод по смете'!$B$7+'Свод по смете'!$B$9) | D8: =-('Свод по смете'!$B$5+'Свод по смете'!$B$6+'Свод по смете'!$B$7+'Свод по смете'!$B$9) | E8: =-('Свод по смете'!$B$5+'Свод по смете'!$B$6+'Свод по смете'!$B$7+'Свод по смете'!$B$9) | F8: =-('Свод по смете'!$B$5+'Свод по смете'!$B$6+'Свод по смете'!$B$7+'Свод по смете'!$B$9) | G8: =-('Свод по смете'!$B$5+'Свод по смете'!$B$6+'Свод по смете'!$B$7+'Свод по смете'!$B$9) | H8: =-('Свод по смете'!$B$5+'Свод по смете'!$B$6+'Свод по смете'!$B$7+'Свод по смете'!$B$9) | I8: =-('Свод по смете'!$B$5+'Свод по смете'!$B$6+'Свод по смете'!$B$7+'Свод по смете'!$B$9) | ... M8: =-('Свод по смете'!$B$5+'Свод по смете'!$B$6+'Свод по смете'!$B$7+'Свод по смете'!$B$9) | N8: =SUM(B8:M8)
A9: Амортизация оборудования | B9: =-'Свод по смете'!$B$8 | C9: =-'Свод по смете'!$B$8 | D9: =-'Свод по смете'!$B$8 | E9: =-'Свод по смете'!$B$8 | F9: =-'Свод по смете'!$B$8 | G9: =-'Свод по смете'!$B$8 | H9: =-'Свод по смете'!$B$8 | I9: =-'Свод по смете'!$B$8 | ... M9: =-'Свод по смете'!$B$8 | N9: =SUM(B9:M9)
A10: Вознаграждение и администрирование субподрядчика | B10: =-('Свод по смете'!$B$11+'Свод по смете'!$B$12) | C10: =-('Свод по смете'!$B$11+'Свод по смете'!$B$12) | D10: =-('Свод по смете'!$B$11+'Свод по смете'!$B$12) | E10: =-('Свод по смете'!$B$11+'Свод по смете'!$B$12) | F10: =-('Свод по смете'!$B$11+'Свод по смете'!$B$12) | G10: =-('Свод по смете'!$B$11+'Свод по смете'!$B$12) | H10: =-('Свод по смете'!$B$11+'Свод по смете'!$B$12) | I10: =-('Свод по смете'!$B$11+'Свод по смете'!$B$12) | ... M10: =-('Свод по смете'!$B$11+'Свод по смете'!$B$12) | N10: =SUM(B10:M10)
A11: Маржа IC Line | B11: =B6+B7+B8+B9+B10 | C11: =C6+C7+C8+C9+C10 | D11: =D6+D7+D8+D9+D10 | E11: =E6+E7+E8+E9+E10 | F11: =F6+F7+F8+F9+F10 | G11: =G6+G7+G8+G9+G10 | H11: =H6+H7+H8+H9+H10 | I11: =I6+I7+I8+I9+I10 | ... M11: =M6+M7+M8+M9+M10 | N11: =SUM(B11:M11)
A12: Маржа IC Line, % от выручки | B12: =IFERROR(B11/B6,0) | C12: =IFERROR(C11/C6,0) | D12: =IFERROR(D11/D6,0) | E12: =IFERROR(E11/E6,0) | F12: =IFERROR(F11/F6,0) | G12: =IFERROR(G11/G6,0) | H12: =IFERROR(H11/H6,0) | I12: =IFERROR(I11/I6,0) | ... N12: =IFERROR(N11/N6,0)
